Workbook
Name F_borne1: PIVOT!$J$76
Name F_borne2: PIVOT!$K$76
Name M_Borne1: PIVOT!$J$75
Name M_borne2: PIVOT!$K$75
Name R_borne1: PIVOT!$J$74
Name R_borne2: PIVOT!$K$74
Name Segment_Education: #N/A
Name Segment_Segment_RFM: #N/A
Name Segment_Tranche_âge: #N/A

Sheet RAW
A1: ID | B1: Year_Birth | C1: Education | D1: Marital_Status | E1: Income | F1: Kidhome | G1: Teenhome | H1: Dt_Customer | I1: Recency | J1: MntWines | K1: MntFruits | L1: MntMeatProducts | M1: MntFishProducts | N1: MntSweetProducts | O1: MntGoldProds | P1: NumDealsPurchases | Q1: NumWebPurchases | R1: NumCatalogPurchases | S1: NumStorePurchases | T1: NumWebVisitsMonth | U1: AcceptedCmp3 | V1: AcceptedCmp4 | W1: AcceptedCmp5 | X1: AcceptedCmp1 | Y1: AcceptedCmp2 | Z1: Complain | AA1: Z_CostContact | AB1: Z_Revenue | AC1: Response
A2: 5524 | B2: 1957 | C2: Graduation | D2: Single | E2: 58138 | F2: 0 | G2: 0 | H2: 04-09-2012 | I2: 58 | J2: 635 | K2: 88 | L2: 546 | M2: 172 | N2: 88 | O2: 88 | P2: 3 | Q2: 8 | R2: 10 | S2: 4 | T2: 7 | U2: 0 | V2: 0 | W2: 0 | X2: 0 | Y2: 0 | Z2: 0 | AA2: 3 | AB2: 11 | AC2: 1
A3: 2174 | B3: 1954 | C3: Graduation | D3: Single | E3: 46344 | F3: 1 | G3: 1 | H3: 08-03-2014 | I3: 38 | J3: 11 | K3: 1 | L3: 6 | M3: 2 | N3: 1 | O3: 6 | P3: 2 | Q3: 1 | R3: 1 | S3: 2 | T3: 5 | U3: 0 | V3: 0 | W3: 0 | X3: 0 | Y3: 0 | Z3: 0 | AA3: 3 | AB3: 11 | AC3: 0
A4: 4141 | B4: 1965 | C4: Graduation | D4: Together | E4: 71613 | F4: 0 | G4: 0 | H4: 21-08-2013 | I4: 26 | J4: 426 | K4: 49 | L4: 127 | M4: 111 | N4: 21 | O4: 42 | P4: 1 | Q4: 8 | R4: 2 | S4: 10 | T4: 4 | U4: 0 | V4: 0 | W4: 0 | X4: 0 | Y4: 0 | Z4: 0 | AA4: 3 | AB4: 11 | AC4: 0
A5: 6182 | B5: 1984 | C5: Graduation | D5: Together | E5: 26646 | F5: 1 | G5: 0 | H5: 10-02-2014 | I5: 26 | J5: 11 | K5: 4 | L5: 20 | M5: 10 | N5: 3 | O5: 5 | P5: 2 | Q5: 2 | R5: 0 | S5: 4 | T5: 6 | U5: 0 | V5: 0 | W5: 0 | X5: 0 | Y5: 0 | Z5: 0 | AA5: 3 | AB5: 11 | AC5: 0
A6: 5324 | B6: 1981 | C6: PhD | D6: Married | E6: 58293 | F6: 1 | G6: 0 | H6: 19-01-2014 | I6: 94 | J6: 173 | K6: 43 | L6: 118 | M6: 46 | N6: 27 | O6: 15 | P6: 5 | Q6: 5 | R6: 3 | S6: 6 | T6: 5 | U6: 0 | V6: 0 | W6: 0 | X6: 0 | Y6: 0 | Z6: 0 | AA6: 3 | AB6: 11 | AC6: 0
A7: 7446 | B7: 1967 | C7: Master | D7: Together | E7: 62513 | F7: 0 | G7: 1 | H7: 09-09-2013 | I7: 16 | J7: 520 | K7: 42 | L7: 98 | M7: 0 | N7: 42 | O7: 14 | P7: 2 | Q7: 6 | R7: 4 | S7: 10 | T7: 6 | U7: 0 | V7: 0 | W7: 0 | X7: 0 | Y7: 0 | Z7: 0 | AA7: 3 | AB7: 11 | AC7: 0
A8: 965 | B8: 1971 | C8: Graduation | D8: Divorced | E8: 55635 | F8: 0 | G8: 1 | H8: 13-11-2012 | I8: 34 | J8: 235 | K8: 65 | L8: 164 | M8: 50 | N8: 49 | O8: 27 | P8: 4 | Q8: 7 | R8: 3 | S8: 7 | T8: 6 | U8: 0 | V8: 0 | W8: 0 | X8: 0 | Y8: 0 | Z8: 0 | AA8: 3 | AB8: 11 | AC8: 0
A9: 6177 | B9: 1985 | C9: PhD | D9: Married | E9: 33454 | F9: 1 | G9: 0 | H9: 08-05-2013 | I9: 32 | J9: 76 | K9: 10 | L9: 56 | M9: 3 | N9: 1 | O9: 23 | P9: 2 | Q9: 4 | R9: 0 | S9: 4 | T9: 8 | U9: 0 | V9: 0 | W9: 0 | X9: 0 | Y9: 0 | Z9: 0 | AA9: 3 | AB9: 11 | AC9: 0
A10: 4855 | B10: 1974 | C10: PhD | D10: Together | E10: 30351 | F10: 1 | G10: 0 | H10: 06-06-2013 | I10: 19 | J10: 14 | K10: 0 | L10: 24 | M10: 3 | N10: 3 | O10: 2 | P10: 1 | Q10: 3 | R10: 0 | S10: 2 | T10: 9 | U10: 0 | V10: 0 | W10: 0 | X10: 0 | Y10: 0 | Z10: 0 | AA10: 3 | AB10: 11 | AC10: 1
A11: 5899 | B11: 1950 | C11: PhD | D11: Together | E11: 5648 | F11: 1 | G11: 1 | H11: 13-03-2014 | I11: 68 | J11: 28 | K11: 0 | L11: 6 | M11: 1 | N11: 1 | O11: 13 | P11: 1 | Q11: 1 | R11: 0 | S11: 0 | T11: 20 | U11: 1 | V11: 0 | W11: 0 | X11: 0 | Y11: 0 | Z11: 0 | AA11: 3 | AB11: 11 | AC11: 0
A12: 1994 | B12: 1983 | C12: Graduation | D12: Married | F12: 1 | G12: 0 | H12: 15-11-2013 | I12: 11 | J12: 5 | K12: 5 | L12: 6 | M12: 0 | N12: 2 | O12: 1 | P12: 1 | Q12: 1 | R12: 0 | S12: 2 | T12: 7 | U12: 0 | V12: 0 | W12: 0 | X12: 0 | Y12: 0 | Z12: 0 | AA12: 3 | AB12: 11 | AC12: 0
A13: 387 | B13: 1976 | C13: Basic | D13: Married | E13: 7500 | F13: 0 | G13: 0 | H13: 13-11-2012 | I13: 59 | J13: 6 | K13: 16 | L13: 11 | M13: 11 | N13: 1 | O13: 16 | P13: 1 | Q13: 2 | R13: 0 | S13: 3 | T13: 8 | U13: 0 | V13: 0 | W13: 0 | X13: 0 | Y13: 0 | Z13: 0 | AA13: 3 | AB13: 11 | AC13: 0
A14: 2125 | B14: 1959 | C14: Graduation | D14: Divorced | E14: 63033 | F14: 0 | G14: 0 | H14: 15-11-2013 | I14: 82 | J14: 194 | K14: 61 | L14: 480 | M14: 225 | N14: 112 | O14: 30 | P14: 1 | Q14: 3 | R14: 4 | S14: 8 | T14: 2 | U14: 0 | V14: 0 | W14: 0 | X14: 0 | Y14: 0 | Z14: 0 | AA14: 3 | AB14: 11 | AC14: 0
A15: 8180 | B15: 1952 | C15: Master | D15: Divorced | E15: 59354 | F15: 1 | G15: 1 | H15: 15-11-2013 | I15: 53 | J15: 233 | K15: 2 | L15: 53 | M15: 3 | N15: 5 | O15: 14 | P15: 3 | Q15: 6 | R15: 1 | S15: 5 | T15: 6 | U15: 0 | V15: 0 | W15: 0 | X15: 0 | Y15: 0 | Z15: 0 | AA15: 3 | AB15: 11 | AC15: 0
A16: 2569 | B16: 1987 | C16: Graduation | D16: Married | E16: 17323 | F16: 0 | G16: 0 | H16: 10-10-2012 | I16: 38 | J16: 3 | K16: 14 | L16: 17 | M16: 6 | N16: 1 | O16: 5 | P16: 1 | Q16: 1 | R16: 0 | S16: 3 | T16: 8 | U16: 0 | V16: 0 | W16: 0 | X16: 0 | Y16: 0 | Z16: 0 | AA16: 3 | AB16: 11 | AC16: 0
A17: 2114 | B17: 1946 | C17: PhD | D17: Single | E17: 82800 | F17: 0 | G17: 0 | H17: 24-11-2012 | I17: 23 | J17: 1006 | K17: 22 | L17: 115 | M17: 59 | N17: 68 | O17: 45 | P17: 1 | Q17: 7 | R17: 6 | S17: 12 | T17: 3 | U17: 0 | V17: 0 | W17: 1 | X17: 1 | Y17: 0 | Z17: 0 | AA17: 3 | AB17: 11 | AC17: 1
A18: 9736 | B18: 1980 | C18: Graduation | D18: Married | E18: 41850 | F18: 1 | G18: 1 | H18: 24-12-2012 | I18: 51 | J18: 53 | K18: 5 | L18: 19 | M18: 2 | N18: 13 | O18: 4 | P18: 3 | Q18: 3 | R18: 0 | S18: 3 | T18: 8 | U18: 0 | V18: 0 | W18: 0 | X18: 0 | Y18: 0 | Z18: 0 | AA18: 3 | AB18: 11 | AC18: 0
A19: 4939 | B19: 1946 | C19: Graduation | D19: Together | E19: 37760 | F19: 0 | G19: 0 | H19: 31-08-2012 | I19: 20 | J19: 84 | K19: 5 | L19: 38 | M19: 150 | N19: 12 | O19: 28 | P19: 2 | Q19: 4 | R19: 1 | S19: 6 | T19: 7 | U19: 0 | V19: 0 | W19: 0 | X19: 0 | Y19: 0 | Z19: 0 | AA19: 3 | AB19: 11 | AC19: 0
A20: 6565 | B20: 1949 | C20: Master | D20: Married | E20: 76995 | F20: 0 | G20: 1 | H20: 28-03-2013 | I20: 91 | J20: 1012 | K20: 80 | L20: 498 | M20: 0 | N20: 16 | O20: 176 | P20: 2 | Q20: 11 | R20: 4 | S20: 9 | T20: 5 | U20: 0 | V20: 0 | W20: 0 | X20: 1 | Y20: 0 | Z20: 0 | AA20: 3 | AB20: 11 | AC20: 0
A21: 2278 | B21: 1985 | C21: 2n Cycle | D21: Single | E21: 33812 | F21: 1 | G21: 0 | H21: 03-11-2012 | I21: 86 | J21: 4 | K21: 17 | L21: 19 | M21: 30 | N21: 24 | O21: 39 | P21: 2 | Q21: 2 | R21: 1 | S21: 3 | T21: 6 | U21: 0 | V21: 0 | W21: 0 | X21: 0 | Y21: 0 | Z21: 0 | AA21: 3 | AB21: 11 | AC21: 0
A22: 9360 | B22: 1982 | C22: Graduation | D22: Married | E22: 37040 | F22: 0 | G22: 0 | H22: 08-08-2012 | I22: 41 | J22: 86 | K22: 2 | L22: 73 | M22: 69 | N22: 38 | O22: 48 | P22: 1 | Q22: 4 | R22: 2 | S22: 5 | T22: 8 | U22: 0 | V22: 0 | W22: 0 | X22: 0 | Y22: 0 | Z22: 0 | AA22: 3 | AB22: 11 | AC22: 0
A23: 5376 | B23: 1979 | C23: Graduation | D23: Married | E23: 2447 | F23: 1 | G23: 0 | H23: 06-01-2013 | I23: 42 | J23: 1 | K23: 1 | L23: 1725 | M23: 1 | N23: 1 | O23: 1 | P23: 15 | Q23: 0 | R23: 28 | S23: 0 | T23: 1 | U23: 0 | V23: 0 | W23: 0 | X23: 0 | Y23: 0 | Z23: 0 | AA23: 3 | AB23: 11 | AC23: 0
A24: 1993 | B24: 1949 | C24: PhD | D24: Married | E24: 58607 | F24: 0 | G24: 1 | H24: 23-12-2012 | I24: 63 | J24: 867 | K24: 0 | L24: 86 | M24: 0 | N24: 0 | O24: 19 | P24: 3 | Q24: 2 | R24: 3 | S24: 9 | T24: 8 | U24: 0 | V24: 1 | W24: 0 | X24: 0 | Y24: 0 | Z24: 0 | AA24: 3 | AB24: 11 | AC24: 0
... A28: 2404 | B28: 1976 | C28: Graduation | D28: Married | E28: 53359 | F28: 1 | G28: 1 | H28: 27-05-2013 | I28: 4 | J28: 173 | K28: 4 | L28: 30 | M28: 3 | N28: 6 | O28: 41 | P28: 4 | Q28: 5 | R28: 1 | S28: 4 | T28: 7 | U28: 0 | V28: 0 | W28: 0 | X28: 0 | Y28: 0 | Z28: 0 | AA28: 3 | AB28: 11 | AC28: 0
A29: 5255 | B29: 1986 | C29: Graduation | D29: Single | F29: 1 | G29: 0 | H29: 20-02-2013 | I29: 19 | J29: 5 | K29: 1 | L29: 3 | M29: 3 | N29: 263 | O29: 362 | P29: 0 | Q29: 27 | R29: 0 | S29: 0 | T29: 1 | U29: 0 | V29: 0 | W29: 0 | X29: 0 | Y29: 0 | Z29: 0 | AA29: 3 | AB29: 11 | AC29: 0
A30: 9422 | B30: 1989 | C30: Graduation | D30: Married | E30: 38360 | F30: 1 | G30: 0 | H30: 31-05-2013 | I30: 26 | J30: 36 | K30: 2 | L30: 42 | M30: 20 | N30: 21 | O30: 10 | P30: 2 | Q30: 2 | R30: 1 | S30: 4 | T30: 3 | U30: 0 | V30: 0 | W30: 0 | X30: 0 | Y30: 0 | Z30: 0 | AA30: 3 | AB30: 11 | AC30: 0
A31: 1966 | B31: 1965 | C31: PhD | D31: Married | E31: 84618 | F31: 0 | G31: 0 | H31: 22-11-2013 | I31: 96 | J31: 684 | K31: 100 | L31: 801 | M31: 21 | N31: 66 | O31: 0 | P31: 1 | Q31: 6 | R31: 9 | S31: 10 | T31: 2 | U31: 0 | V31: 0 | W31: 1 | X31: 0 | Y31: 0 | Z31: 0 | AA31: 3 | AB31: 11 | AC31: 0
A32: 6864 | B32: 1989 | C32: Master | D32: Divorced | E32: 10979 | F32: 0 | G32: 0 | H32: 22-05-2014 | I32: 34 | J32: 8 | K32: 4 | L32: 10 | M32: 2 | N32: 2 | O32: 4 | P32: 2 | Q32: 3 | R32: 0 | S32: 3 | T32: 5 | U32: 0 | V32: 0 | W32: 0 | X32: 0 | Y32: 0 | Z32: 0 | AA32: 3 | AB32: 11 | AC32: 0
A33: 3033 | B33: 1963 | C33: Master | D33: Together | E33: 38620 | F33: 0 | G33: 0 | H33: 11-05-2013 | I33: 56 | J33: 112 | K33: 17 | L33: 44 | M33: 34 | N33: 22 | O33: 89 | P33: 1 | Q33: 2 | R33: 5 | S33: 3 | T33: 3 | U33: 0 | V33: 0 | W33: 0 | X33: 0 | Y33: 0 | Z33: 0 | AA33: 3 | AB33: 11 | AC33: 0
A34: 5710 | B34: 1970 | C34: Graduation | D34: Together | E34: 40548 | F34: 0 | G34: 1 | H34: 10-10-2012 | I34: 31 | J34: 110 | K34: 0 | L34: 5 | M34: 2 | N34: 0 | O34: 3 | P34: 2 | Q34: 2 | R34: 1 | S34: 4 | T34: 5 | U34: 0 | V34: 1 | W34: 0 | X34: 0 | Y34: 0 | Z34: 0 | AA34: 3 | AB34: 11 | AC34: 0
A35: 7373 | B35: 1952 | C35: PhD | D35: Divorced | E35: 46610 | F35: 0 | G35: 2 | H35: 29-10-2012 | I35: 8 | J35: 96 | K35: 12 | L35: 96 | M35: 33 | N35: 22 | O35: 43 | P35: 6 | Q35: 4 | R35: 1 | S35: 6 | T35: 6 | U35: 0 | V35: 0 | W35: 0 | X35: 0 | Y35: 0 | Z35: 0 | AA35: 3 | AB35: 11 | AC35: 1
A36: 8755 | B36: 1946 | C36: Master | D36: Married | E36: 68657 | F36: 0 | G36: 0 | H36: 20-02-2013 | I36: 4 | J36: 482 | K36: 34 | L36: 471 | M36: 119 | N36: 68 | O36: 22 | P36: 1 | Q36: 3 | R36: 5 | S36: 9 | T36: 7 | U36: 0 | V36: 0 | W36: 0 | X36: 0 | Y36: 0 | Z36: 0 | AA36: 3 | AB36: 11 | AC36: 0
A37: 10738 | B37: 1951 | C37: Master | D37: Single | E37: 49389 | F37: 1 | G37: 1 | H37: 29-08-2013 | I37: 55 | J37: 40 | K37: 0 | L37: 19 | M37: 2 | N37: 1 | O37: 3 | P37: 1 | Q37: 2 | R37: 0 | S37: 3 | T37: 7 | U37: 0 | V37: 0 | W37: 0 | X37: 0 | Y37: 0 | Z37: 0 | AA37: 3 | AB37: 11 | AC37: 0
A38: 4339 | B38: 1970 | C38: PhD | D38: Married | E38: 67353 | F38: 0 | G38: 1 | H38: 31-12-2013 | I38: 37 | J38: 702 | K38: 17 | L38: 151 | M38: 0 | N38: 8 | O38: 35 | P38: 5 | Q38: 5 | R38: 6 | S38: 12 | T38: 2 | U38: 0 | V38: 0 | W38: 0 | X38: 0 | Y38: 0 | Z38: 0 | AA38: 3 | AB38: 11 | AC38: 0
A39: 10755 | B39: 1976 | C39: 2n Cycle | D39: Married | E39: 23718 | F39: 1 | G39: 0 | H39: 02-09-2013 | I39: 76 | J39: 6 | K39: 3 | L39: 14 | M39: 15 | N39: 7 | O39: 36 | P39: 3 | Q39: 3 | R39: 1 | S39: 2 | T39: 7 | U39: 0 | V39: 0 | W39: 0 | X39: 0 | Y39: 0 | Z39: 0 | AA39: 3 | AB39: 11 | AC39: 0
A40: 8595 | B40: 1973 | C40: Graduation | D40: Widow | E40: 42429 | F40: 0 | G40: 1 | H40: 11-02-2014 | I40: 99 | J40: 55 | K40: 0 | L40: 6 | M40: 2 | N40: 0 | O40: 4 | P40: 2 | Q40: 1 | R40: 1 | S40: 3 | T40: 5 | U40: 0 | V40: 0 | W40: 0 | X40: 0 | Y40: 0 | Z40: 0 | AA40: 3 | AB40: 11 | AC40: 0
A41: 2968 | B41: 1943 | C41: PhD | D41: Divorced | E41: 48948 | F41: 0 | G41: 0 | H41: 01-02-2013 | I41: 53 | J41: 437 | K41: 8 | L41: 206 | M41: 160 | N41: 49 | O41: 42 | P41: 2 | Q41: 7 | R41: 10 | S41: 5 | T41: 6 | U41: 1 | V41: 0 | W41: 0 | X41: 0 | Y41: 0 | Z41: 0 | AA41: 3 | AB41: 11 | AC41: 1
... A44: 8430 | B44: 1957 | C44: Graduation | D44: Together | E44: 21994 | F44: 0 | G44: 1 | H44: 24-12-2012 | I44: 4 | J44: 9 | K44: 0 | L44: 6 | M44: 3 | N44: 1 | O44: 3 | P44: 1 | Q44: 0 | R44: 0 | S44: 3 | T44: 5 | U44: 0 | V44: 0 | W44: 0 | X44: 0 | Y44: 0 | Z44: 0 | AA44: 3 | AB44: 11 | AC44: 0
A45: 7281 | B45: 1959 | C45: PhD | D45: Single | F45: 0 | G45: 0 | H45: 05-11-2013 | I45: 80 | J45: 81 | K45: 11 | L45: 50 | M45: 3 | N45: 2 | O45: 39 | P45: 1 | Q45: 1 | R45: 3 | S45: 4 | T45: 2 | U45: 0 | V45: 0 | W45: 0 | X45: 0 | Y45: 0 | Z45: 0 | AA45: 3 | AB45: 11 | AC45: 0
...

Sheet CLEAN
A1: ID | B1: Année de naissance | C1: Âge | D1: Tranche_âge | E1: Education | F1: Statut_marital | G1: Revenus | H1: Enfantmaison | I1: AdoMaison | J1: Enfant_total | K1: Date_inscription client | L1: Ancienneté client | M1: R_Récence | N1: F_TOTAL_achat | O1: M_TOTAL_dépensé | P1: R_SCORE | Q1: F_SCORE | R1: M_SCORE | S1: RFM_SCORE | T1: Segment_RFM | U1: Montant_Vin_2ans | V1: Montant_Fruits_2ans | W1: Montant_Viande_2ans | X1: Montant_Poisson_2ans | Y1: Montant_Sucreries_2ans | Z1: Montant_Or_2ans | AA1: NbrAchatsRemise | AB1: NbrAchatWeb | AC1: NbrAchatCatalogue | AD1: NbrAchatMagasin | AE1: Nbr de visite web (last month) | AF1: Campagne3Acceptée | AG1: Campagne4Acceptée | AH1: Campagne5Acceptée | AI1: Campagne1Acceptée | AJ1: Campagne2Acceptée | AK1: Réclamation | AL1: Coût contact client | AM1: Revenue client | AN1: Réponse dernière campagne
A2: 9432 | B2: 1977 | C2: =YEAR(TODAY())-CLEAN!$B2 -> 48 | D2: 45-59 ans | E2: BAC+3 | F2: Conjoint | G2: 666666 | H2: 1 | I2: 0 | J2: =CLEAN!$H2+CLEAN!$I2 -> 1 | K2: 41427 | L2: =YEAR(TODAY())-YEAR(CLEAN!$K2) -> 12 | M2: 23 | N2: =SUM(CLEAN!$AB2:$AE2) -> 13 | O2: =CLEAN!$U2+CLEAN!$V2+CLEAN!$W2+CLEAN!$X2+CLEAN!$Y2+CLEAN!$Z2 -> 62 | P2: =IF(CLEAN!$M2<=32,3,IF(CLEAN!$M2<=65,2,1)) -> 3 | Q2: =IF(Table_Market[[#This Row],[F_TOTAL_achat]]<=14,1,IF(Table_Market[[#This Row],[F_TOTAL_achat]]<=21,2,3)) -> 1 | R2: =IF(Table_Market[[#This Row],[M_TOTAL_dépensé]]<=115,1,IF(Table_Market[[#This Row],[M_TOTAL_dépensé]]<=833,2,3)) -> 1 | S2: =Table_Market[[#This Row],[R_SCORE]]&Table_Market[[#This Row],[F_SCORE]]&Table_Market[[#This Row],[M_SCORE]] -> 311 | T2: =IF(Table_Market[[#This Row],[RFM_SCORE]]="333","Clients élites",IF(LEFT(Table_Market[[#This Row],[RFM_SCORE]],1)="3","Récents prometteurs",IF(LEFT(Table_Market[[#This Row],[RFM_SCORE]],1)="1","Inactifs",IF(AND(LEFT(Table_Market[[#This Row],[RFM_SCORE]],1)>="2",MID(Table_Market[[#This Row],[RFM_SCORE]],2,1)>="2",RIGHT(Table_Market[[#This Row],[RFM_SCORE]],1)>="2"),"Fidèles rentables","Occasionnels")))) -> Récents prometteurs | U2: 9 | V2: 14 | W2: 18 | X2: 8 | Y2: 1 | Z2: 12 | AA2: 4 | AB2: 3 | AC2: 1 | AD2: 3 | AE2: 6 | AF2: 0 | AG2: 0 | AH2: 0 | AI2: 0 | AJ2: 0 | AK2: 0 | AL2: 3 | AM2: 11 | AN2: 0
A3: 1503 | B3: 1976 | C3: =YEAR(TODAY())-CLEAN!$B3 -> 49 | D3: 45-59 ans | E3: Doctorat | F3: Conjoint | G3: 162397 | H3: 1 | I3: 1 | J3: =CLEAN!$H3+CLEAN!$I3 -> 2 | K3: 41428 | L3: =YEAR(TODAY())-YEAR(CLEAN!$K3) -> 12 | M3: 31 | N3: =SUM(CLEAN!$AB3:$AE3) -> 2 | O3: =CLEAN!$U3+CLEAN!$V3+CLEAN!$W3+CLEAN!$X3+CLEAN!$Y3+CLEAN!$Z3 -> 107 | P3: =IF(CLEAN!$M3<=32,3,IF(CLEAN!$M3<=65,2,1)) -> 3 | Q3: =IF(Table_Market[[#This Row],[F_TOTAL_achat]]<=14,1,IF(Table_Market[[#This Row],[F_TOTAL_achat]]<=21,2,3)) -> 1 | R3: =IF(Table_Market[[#This Row],[M_TOTAL_dépensé]]<=115,1,IF(Table_Market[[#This Row],[M_TOTAL_dépensé]]<=833,2,3)) -> 1 | S3: =Table_Market[[#This Row],[R_SCORE]]&Table_Market[[#This Row],[F_SCORE]]&Table_Market[[#This Row],[M_SCORE]] -> 311 | T3: =IF(Table_Market[[#This Row],[RFM_SCORE]]="333","Clients élites",IF(LEFT(Table_Market[[#This Row],[RFM_SCORE]],1)="3","Récents prometteurs",IF(LEFT(Table_Market[[#This Row],[RFM_SCORE]],1)="1","Inactifs",IF(AND(LEFT(Table_Market[[#This Row],[RFM_SCORE]],1)>="2",MID(Table_Market[[#This Row],[RFM_SCORE]],2,1)>="2",RIGHT(Table_Market[[#This Row],[RFM_SCORE]],1)>="2"),"Fidèles rentables","Occasionnels")))) -> Récents prometteurs | U3: 85 | V3: 1 | W3: 16 | X3: 2 | Y3: 1 | Z3: 2 | AA3: 0 | AB3: 0 | AC3: 0 | AD3: 1 | AE3: 1 | AF3: 0 | AG3: 0 | AH3: 0 | AI3: 0 | AJ3: 0 | AK3: 0 | AL3: 3 | AM3: 11 | AN3: 0
A4: 1501 | B4: 1982 | C4: =YEAR(TODAY())-CLEAN!$B4 -> 43 | D4: 30-44 ans | E4: Doctorat | F4: Marié | G4: 160803 | H4: 0 | I4: 0 | J4: =CLEAN!$H4+CLEAN!$I4 -> 0 | K4: 41125 | L4: =YEAR(TODAY())-YEAR(CLEAN!$K4) -> 13 | M4: 21 | N4: =SUM(CLEAN!$AB4:$AE4) -> 29 | O4: =CLEAN!$U4+CLEAN!$V4+CLEAN!$W4+CLEAN!$X4+CLEAN!$Y4+CLEAN!$Z4 -> 1717 | P4: =IF(CLEAN!$M4<=32,3,IF(CLEAN!$M4<=65,2,1)) -> 3 | Q4: =IF(Table_Market[[#This Row],[F_TOTAL_achat]]<=14,1,IF(Table_Market[[#This Row],[F_TOTAL_achat]]<=21,2,3)) -> 3 | R4: =IF(Table_Market[[#This Row],[M_TOTAL_dépensé]]<=115,1,IF(Table_Market[[#This Row],[M_TOTAL_dépensé]]<=833,2,3)) -> 3 | S4: =Table_Market[[#This Row],[R_SCORE]]&Table_Market[[#This Row],[F_SCORE]]&Table_Market[[#This Row],[M_SCORE]] -> 333 | T4: =IF(Table_Market[[#This Row],[RFM_SCORE]]="333","Clients élites",IF(LEFT(Table_Market[[#This Row],[RFM_SCORE]],1)="3","Récents prometteurs",IF(LEFT(Table_Market[[#This Row],[RFM_SCORE]],1)="1","Inactifs",IF(AND(LEFT(Table_Market[[#This Row],[RFM_SCORE]],1)>="2",MID(Table_Market[[#This Row],[RFM_SCORE]],2,1)>="2",RIGHT(Table_Market[[#This Row],[RFM_SCORE]],1)>="2"),"Fidèles rentables","Occasionnels")))) -> Clients élites | U4: 55 | V4: 16 | W4: 1622 | X4: 17 | Y4: 3 | Z4: 4 | AA4: 15 | AB4: 0 | AC4: 28 | AD4: 1 | AE4: 0 | AF4: 0 | AG4: 0 | AH4: 0 | AI4: 0 | AJ4: 0 | AK4: 0 | AL4: 3 | AM4: 11 | AN4: 0
A5: 5336 | B5: 1971 | C5: =YEAR(TODAY())-CLEAN!$B5 -> 54 | D5: 45-59 ans | E5: BAC+5 | F5: Conjoint | G5: 157733 | H5: 1 | I5: 0 | J5: =CLEAN!$H5+CLEAN!$I5 -> 1 | K5: 41429 | L5: =YEAR(TODAY())-YEAR(CLEAN!$K5) -> 12 | M5: 37 | N5: =SUM(CLEAN!$AB5:$AE5) -> 3 | O5: =CLEAN!$U5+CLEAN!$V5+CLEAN!$W5+CLEAN!$X5+CLEAN!$Y5+CLEAN!$Z5 -> 59 | P5: =IF(CLEAN!$M5<=32,3,IF(CLEAN!$M5<=65,2,1)) -> 2 | Q5: =IF(Table_Market[[#This Row],[F_TOTAL_achat]]<=14,1,IF(Table_Market[[#This Row],[F_TOTAL_achat]]<=21,2,3)) -> 1 | R5: =IF(Table_Market[[#This Row],[M_TOTAL_dépensé]]<=115,1,IF(Table_Market[[#This Row],[M_TOTAL_dépensé]]<=833,2,3)) -> 1 | S5: =Table_Market[[#This Row],[R_SCORE]]&Table_Market[[#This Row],[F_SCORE]]&Table_Market[[#This Row],[M_SCORE]] -> 211 | T5: =IF(Table_Market[[#This Row],[RFM_SCORE]]="333","Clients élites",IF(LEFT(Table_Market[[#This Row],[RFM_SCORE]],1)="3","Récents prometteurs",IF(LEFT(Table_Market[[#This Row],[RFM_SCORE]],1)="1","Inactifs",IF(AND(LEFT(Table_Market[[#This Row],[RFM_SCORE]],1)>="2",MID(Table_Market[[#This Row],[RFM_SCORE]],2,1)>="2",RIGHT(Table_Market[[#This Row],[RFM_SCORE]],1)>="2"),"Fidèles rentables","Occasionnels")))) -> Occasionnels | U5: 39 | V5: 1 | W5: 9 | X5: 2 | Y5: 0 | Z5: 8 | AA5: 0 | AB5: 1 | AC5: 0 | AD5: 1 | AE5: 1 | AF5: 0 | AG5: 0 | AH5: 0 | AI5: 0 | AJ5: 0 | AK5: 0 | AL5: 3 | AM5: 11 | AN5: 0
A6: 8475 | B6: 1973 | C6: =YEAR(TODAY())-CLEAN!$B6 -> 52 | D6: 45-59 ans | E6: Doctorat | F6: Marié | G6: 157243 | H6: 0 | I6: 1 | J6: =CLEAN!$H6+CLEAN!$I6 -> 1 | K6: 41699 | L6: =YEAR(TODAY())-YEAR(CLEAN!$K6) -> 11 | M6: 98 | N6: =SUM(CLEAN!$AB6:$AE6) -> 22 | O6: =CLEAN!$U6+CLEAN!$V6+CLEAN!$W6+CLEAN!$X6+CLEAN!$Y6+CLEAN!$Z6 -> 1608 | P6: =IF(CLEAN!$M6<=32,3,IF(CLEAN!$M6<=65,2,1)) -> 1 | Q6: =IF(Table_Market[[#This Row],[F_TOTAL_achat]]<=14,1,IF(Table_Market[[#This Row],[F_TOTAL_achat]]<=21,2,3)) -> 3 | R6: =IF(Table_Market[[#This Row],[M_TOTAL_dépensé]]<=115,1,IF(Table_Market[[#This Row],[M_TOTAL_dépensé]]<=833,2,3)) -> 3 | S6: =Table_Market[[#This Row],[R_SCORE]]&Table_Market[[#This Row],[F_SCORE]]&Table_Market[[#This Row],[M_SCORE]] -> 133 | T6: =IF(Table_Market[[#This Row],[RFM_SCORE]]="333","Clients élites",IF(LEFT(Table_Market[[#This Row],[RFM_SCORE]],1)="3","Récents prometteurs",IF(LEFT(Table_Market[[#This Row],[RFM_SCORE]],1)="1","Inactifs",IF(AND(LEFT(Table_Market[[#This Row],[RFM_SCORE]],1)>="2",MID(Table_Market[[#This Row],[RFM_SCORE]],2,1)>="2",RIGHT(Table_Market[[#This Row],[RFM_SCORE]],1)>="2"),"Fidèles rentables","Occasionnels")))) -> Inactifs | U6: 20 | V6: 2 | W6: 1582 | X6: 1 | Y6: 2 | Z6: 1 | AA6: 15 | AB6: 0 | AC6: 22 | AD6: 0 | AE6: 0 | AF6: 0 | AG6: 0 | AH6: 0 | AI6: 0 | AJ6: 0 | AK6: 0 | AL6: 3 | AM6: 11 | AN6: 0
A7: 4931 | B7: 1977 | C7: =YEAR(TODAY())-CLEAN!$B7 -> 48 | D7: 45-59 ans | E7: BAC+3 | F7: Conjoint | G7: 157146 | H7: 0 | I7: 0 | J7: =CLEAN!$H7+CLEAN!$I7 -> 0 | K7: 41393 | L7: =YEAR(TODAY())-YEAR(CLEAN!$K7) -> 12 | M7: 13 | N7: =SUM(CLEAN!$AB7:$AE7) -> 29 | O7: =CLEAN!$U7+CLEAN!$V7+CLEAN!$W7+CLEAN!$X7+CLEAN!$Y7+CLEAN!$Z7 -> 1730 | P7: =IF(CLEAN!$M7<=32,3,IF(CLEAN!$M7<=65,2,1)) -> 3 | Q7: =IF(Table_Market[[#This Row],[F_TOTAL_achat]]<=14,1,IF(Table_Market[[#This Row],[F_TOTAL_achat]]<=21,2,3)) -> 3 | R7: =IF(Table_Market[[#This Row],[M_TOTAL_dépensé]]<=115,1,IF(Table_Market[[#This Row],[M_TOTAL_dépensé]]<=833,2,3)) -> 3 | S7: =Table_Market[[#This Row],[R_SCORE]]&Table_Market[[#This Row],[F_SCORE]]&Table_Market[[#This Row],[M_SCORE]] -> 333 | T7: =IF(Table_Market[[#This Row],[RFM_SCORE]]="333","Clients élites",IF(LEFT(Table_Market[[#This Row],[RFM_SCORE]],1)="3","Récents prometteurs",IF(LEFT(Table_Market[[#This Row],[RFM_SCORE]],1)="1","Inactifs",IF(AND(LEFT(Table_Market[[#This Row],[RFM_SCORE]],1)>="2",MID(Table_Market[[#This Row],[RFM_SCORE]],2,1)>="2",RIGHT(Table_Market[[#This Row],[RFM_SCORE]],1)>="2"),"Fidèles rentables","Occasionnels")))) -> Clients élites | U7: 1 | V7: 0 | W7: 1725 | X7: 2 | Y7: 1 | Z7: 1 | AA7: 0 | AB7: 0 | AC7: 28 | AD7: 0 | AE7: 1 | AF7: 0 | AG7: 0 | AH7: 0 | AI7: 0 | AJ7: 0 | AK7: 0 | AL7: 3 | AM7: 11 | AN7: 0
A8: 11181 | B8: 1949 | C8: =YEAR(TODAY())-CLEAN!$B8 -> 76 | D8: 60 ans et + | E8: Doctorat | F8: Marié | G8: 156924 | H8: 0 | I8: 0 | J8: =CLEAN!$H8+CLEAN!$I8 -> 0 | K8: 41515 | L8: =YEAR(TODAY())-YEAR(CLEAN!$K8) -> 12 | M8: 85 | N8: =SUM(CLEAN!$AB8:$AE8) -> 0 | O8: =CLEAN!$U8+CLEAN!$V8+CLEAN!$W8+CLEAN!$X8+CLEAN!$Y8+CLEAN!$Z8 -> 8 | P8: =IF(CLEAN!$M8<=32,3,IF(CLEAN!$M8<=65,2,1)) -> 1 | Q8: =IF(Table_Market[[#This Row],[F_TOTAL_achat]]<=14,1,IF(Table_Market[[#This Row],[F_TOTAL_achat]]<=21,2,3)) -> 1 | R8: =IF(Table_Market[[#This Row],[M_TOTAL_dépensé]]<=115,1,IF(Table_Market[[#This Row],[M_TOTAL_dépensé]]<=833,2,3)) -> 1 | S8: =Table_Market[[#This Row],[R_SCORE]]&Table_Market[[#This Row],[F_SCORE]]&Table_Market[[#This Row],[M_SCORE]] -> 111 | T8: =IF(Table_Market[[#This Row],[RFM_SCORE]]="333","Clients élites",IF(LEFT(Table_Market[[#This Row],[RFM_SCORE]],1)="3","Récents prometteurs",IF(LEFT(Table_Market[[#This Row],[RFM_SCORE]],1)="1","Inactifs",IF(AND(LEFT(Table_Market[[#This Row],[RFM_SCORE]],1)>="2",MID(Table_Market[[#This Row],[RFM_SCORE]],2,1)>="2",RIGHT(Table_Market[[#This Row],[RFM_SCORE]],1)>="2"),"Fidèles rentables","Occasionnels")))) -> Inactifs | U8: 2 | V8: 1 | W8: 2 | X8: 1 | Y8: 1 | Z8: 1 | AA8: 0 | AB8: 0 | AC8: 0 | AD8: 0 | AE8: 0 | AF8: 0 | AG8: 0 | AH8: 0 | AI8: 0 | AJ8: 0 | AK8: 0 | AL8: 3 | AM8: 11 | AN8: 0
A9: 5555 | B9: 1975 | C9: =YEAR(TODAY())-CLEAN!$B9 -> 50 | D9: 45-59 ans | E9: BAC+3 | F9: Divorcé | G9: 153924 | H9: 0 | I9: 0 | J9: =CLEAN!$H9+CLEAN!$I9 -> 0 | K9: 41677 | L9: =YEAR(TODAY())-YEAR(CLEAN!$K9) -> 11 | M9: 81 | N9: =SUM(CLEAN!$AB9:$AE9) -> 0 | O9: =CLEAN!$U9+CLEAN!$V9+CLEAN!$W9+CLEAN!$X9+CLEAN!$Y9+CLEAN!$Z9 -> 6 | P9: =IF(CLEAN!$M9<=32,3,IF(CLEAN!$M9<=65,2,1)) -> 1 | Q9: =IF(Table_Market[[#This Row],[F_TOTAL_achat]]<=14,1,IF(Table_Market[[#This Row],[F_TOTAL_achat]]<=21,2,3)) -> 1 | R9: =IF(Table_Market[[#This Row],[M_TOTAL_dépensé]]<=115,1,IF(Table_Market[[#This Row],[M_TOTAL_dépensé]]<=833,2,3)) -> 1 | S9: =Table_Market[[#This Row],[R_SCORE]]&Table_Market[[#This Row],[F_SCORE]]&Table_Market[[#This Row],[M_SCORE]] -> 111 | T9: =IF(Table_Market[[#This Row],[RFM_SCORE]]="333","Clients élites",IF(LEFT(Table_Market[[#This Row],[RFM_SCORE]],1)="3","Récents prometteurs",IF(LEFT(Table_Market[[#This Row],[RFM_SCORE]],1)="1","Inactifs",IF(AND(LEFT(Table_Market[[#This Row],[RFM_SCORE]],1)>="2",MID(Table_Market[[#This Row],[RFM_SCORE]],2,1)>="2",RIGHT(Table_Market[[#This Row],[RFM_SCORE]],1)>="2"),"Fidèles rentables","Occasionnels")))) -> Inactifs | U9: 1 | V9: 1 | W9: 1 | X9: 1 | Y9: 1 | Z9: 1 | AA9: 0 | AB9: 0 | AC9: 0 | AD9: 0 | AE9: 0 | AF9: 0 | AG9: 0 | AH9: 0 | AI9: 0 | AJ9: 0 | AK9: 0 | AL9: 3 | AM9: 11 | AN9: 0
A10: 4619 | B10: 1945 | C10: =YEAR(TODAY())-CLEAN!$B10 -> 80 | D10: 60 ans et + | E10: Doctorat | F10: Célibataire | G10: 113734 | H10: 0 | I10: 0 | J10: =CLEAN!$H10+CLEAN!$I10 -> 0 | K10: 41787 | L10: =YEAR(TODAY())-YEAR(CLEAN!$K10) -> 11 | M10: 9 | N10: =SUM(CLEAN!$AB10:$AE10) -> 28 | O10: =CLEAN!$U10+CLEAN!$V10+CLEAN!$W10+CLEAN!$X10+CLEAN!$Y10+CLEAN!$Z10 -> 277 | P10: =IF(CLEAN!$M10<=32,3,IF(CLEAN!$M10<=65,2,1)) -> 3 | Q10: =IF(Table_Market[[#This Row],[F_TOTAL_achat]]<=14,1,IF(Table_Market[[#This Row],[F_TOTAL_achat]]<=21,2,3)) -> 3 | R10: =IF(Table_Market[[#This Row],[M_TOTAL_dépensé]]<=115,1,IF(Table_Market[[#This Row],[M_TOTAL_dépensé]]<=833,2,3)) -> 2 | S10: =Table_Market[[#This Row],[R_SCORE]]&Table_Market[[#This Row],[F_SCORE]]&Table_Market[[#This Row],[M_SCORE]] -> 332 | T10: =IF(Table_Market[[#This Row],[RFM_SCORE]]="333","Clients élites",IF(LEFT(Table_Market[[#This Row],[RFM_SCORE]],1)="3","Récents prometteurs",IF(LEFT(Table_Market[[#This Row],[RFM_SCORE]],1)="1","Inactifs",IF(AND(LEFT(Table_Market[[#This Row],[RFM_SCORE]],1)>="2",MID(Table_Market[[#This Row],[RFM_SCORE]],2,1)>="2",RIGHT(Table_Market[[#This Row],[RFM_SCORE]],1)>="2"),"Fidèles rentables","Occasionnels")))) -> Récents prometteurs | U10: 6 | V10: 2 | W10: 3 | X10: 1 | Y10: 262 | Z10: 3 | AA10: 0 | AB10: 27 | AC10: 0 | AD10: 0 | AE10: 1 | AF10: 0 | AG10: 0 | AH10: 0 | AI10: 0 | AJ10: 0 | AK10: 0 | AL10: 3 | AM10: 11 | AN10: 0
A11: 4611 | B11: 1970 | C11: =YEAR(TODAY())-CLEAN!$B11 -> 55 | D11: 45-59 ans | E11: BAC+3 | F11: Conjoint | G11: 105471 | H11: 0 | I11: 0 | J11: =CLEAN!$H11+CLEAN!$I11 -> 0 | K11: 41295 | L11: =YEAR(TODAY())-YEAR(CLEAN!$K11) -> 12 | M11: 36 | N11: =SUM(CLEAN!$AB11:$AE11) -> 33 | O11: =CLEAN!$U11+CLEAN!$V11+CLEAN!$W11+CLEAN!$X11+CLEAN!$Y11+CLEAN!$Z11 -> 1724 | P11: =IF(CLEAN!$M11<=32,3,IF(CLEAN!$M11<=65,2,1)) -> 2 | Q11: =IF(Table_Market[[#This Row],[F_TOTAL_achat]]<=14,1,IF(Table_Market[[#This Row],[F_TOTAL_achat]]<=21,2,3)) -> 3 | R11: =IF(Table_Market[[#This Row],[M_TOTAL_dépensé]]<=115,1,IF(Table_Market[[#This Row],[M_TOTAL_dépensé]]<=833,2,3)) -> 3 | S11: =Table_Market[[#This Row],[R_SCORE]]&Table_Market[[#This Row],[F_SCORE]]&Table_Market[[#This Row],[M_SCORE]] -> 233 | T11: =IF(Table_Market[[#This Row],[RFM_SCORE]]="333","Clients élites",IF(LEFT(Table_Market[[#This Row],[RFM_SCORE]],1)="3","Récents prometteurs",IF(LEFT(Table_Market[[#This Row],[RFM_SCORE]],1)="1","Inactifs",IF(AND(LEFT(Table_Market[[#This Row],[RFM_SCORE]],1)>="2",MID(Table_Market[[#This Row],[RFM_SCORE]],2,1)>="2",RIGHT(Table_Market[[#This Row],[RFM_SCORE]],1)>="2"),"Fidèles rentables","Occasionnels")))) -> Fidèles rentables | U11: 1009 | V11: 181 | W11: 104 | X11: 202 | Y11: 21 | Z11: 207 | AA11: 0 | AB11: 9 | AC11: 8 | AD11: 13 | AE11: 3 | AF11: 0 | AG11: 0 | AH11: 1 | AI11: 1 | AJ11: 0 | AK11: 0 | AL11: 3 | AM11: 11 | AN11: 1
A12: 10089 | B12: 1974 | C12: =YEAR(TODAY())-CLEAN!$B12 -> 51 | D12: 45-59 ans | E12: BAC+3 | F12: Divorcé | G12: 102692 | H12: 0 | I12: 0 | J12: =CLEAN!$H12+CLEAN!$I12 -> 0 | K12: 41369 | L12: =YEAR(TODAY())-YEAR(CLEAN!$K12) -> 12 | M12: 5 | N12: =SUM(CLEAN!$AB12:$AE12) -> 30 | O12: =CLEAN!$U12+CLEAN!$V12+CLEAN!$W12+CLEAN!$X12+CLEAN!$Y12+CLEAN!$Z12 -> 1112 | P12: =IF(CLEAN!$M12<=32,3,IF(CLEAN!$M12<=65,2,1)) -> 3 | Q12: =IF(Table_Market[[#This Row],[F_TOTAL_achat]]<=14,1,IF(Table_Market[[#This Row],[F_TOTAL_achat]]<=21,2,3)) -> 3 | R12: =IF(Table_Market[[#This Row],[M_TOTAL_dépensé]]<=115,1,IF(Table_Market[[#This Row],[M_TOTAL_dépensé]]<=833,2,3)) -> 3 | S12: =Table_Market[[#This Row],[R_SCORE]]&Table_Market[[#This Row],[F_SCORE]]&Table_Market[[#This Row],[M_SCORE]] -> 333 | T12: =IF(Table_Market[[#This Row],[RFM_SCORE]]="333","Clients élites",IF(LEFT(Table_Market[[#This Row],[RFM_SCORE]],1)="3","Récents prometteurs",IF(LEFT(Table_Market[[#This Row],[RFM_SCORE]],1)="1","Inactifs",IF(AND(LEFT(Table_Market[[#This Row],[RFM_SCORE]],1)>="2",MID(Table_Market[[#This Row],[RFM_SCORE]],2,1)>="2",RIGHT(Table_Market[[#This Row],[RFM_SCORE]],1)>="2"),"Fidèles rentables","Occasionnels")))) -> Clients élites | U12: 168 | V12: 148 | W12: 444 | X12: 32 | Y12: 172 | Z12: 148 | AA12: 1 | AB12: 6 | AC12: 9 | AD12: 13 | AE12: 2 | AF12: 0 | AG12: 1 | AH12: 1 | AI12: 1 | AJ12: 1 | AK12: 0 | AL12: 3 | AM12: 11 | AN12: 1
A13: 2798 | B13: 1977 | C13: =YEAR(TODAY())-CLEAN!$B13 -> 48 | D13: 45-59 ans | E13: Doctorat | F13: Conjoint | G13: 102160 | H13: 0 | I13: 0 | J13: =CLEAN!$H13+CLEAN!$I13 -> 0 | K13: 41215 | L13: =YEAR(TODAY())-YEAR(CLEAN!$K13) -> 13 | M13: 54 | N13: =SUM(CLEAN!$AB13:$AE13) -> 30 | O13: =CLEAN!$U13+CLEAN!$V13+CLEAN!$W13+CLEAN!$X13+CLEAN!$Y13+CLEAN!$Z13 -> 1240 | P13: =IF(CLEAN!$M13<=32,3,IF(CLEAN!$M13<=65,2,1)) -> 2 | Q13: =IF(Table_Market[[#This Row],[F_TOTAL_achat]]<=14,1,IF(Table_Market[[#This Row],[F_TOTAL_achat]]<=21,2,3)) -> 3 | R13: =IF(Table_Market[[#This Row],[M_TOTAL_dépensé]]<=115,1,IF(Table_Market[[#This Row],[M_TOTAL_dépensé]]<=833,2,3)) -> 3 | S13: =Table_Market[[#This Row],[R_SCORE]]&Table_Market[[#This Row],[F_SCORE]]&Table_Market[[#This Row],[M_SCORE]] -> 233 | T13: =IF(Table_Market[[#This Row],[RFM_SCORE]]="333","Clients élites",IF(LEFT(Table_Market[[#This Row],[RFM_SCORE]],1)="3","Récents prometteurs",IF(LEFT(Table_Market[[#This Row],[RFM_SCORE]],1)="1","Inactifs",IF(AND(LEFT(Table_Market[[#This Row],[RFM_SCORE]],1)>="2",MID(Table_Market[[#This Row],[RFM_SCORE]],2,1)>="2",RIGHT(Table_Market[[#This Row],[RFM_SCORE]],1)>="2"),"Fidèles rentables","Occasionnels")))) -> Fidèles rentables | U13: 763 | V13: 29 | W13: 138 | X13: 76 | Y13: 176 | Z13: 58 | AA13: 0 | AB13: 7 | AC13: 9 | AD13: 10 | AE13: 4 | AF13: 0 | AG13: 1 | AH13: 1 | AI13: 1 | AJ13: 0 | AK13: 0 | AL13: 3 | AM13: 11 | AN13: 1
... A63: 6421 | B63: 1961 | C63: =YEAR(TODAY())-CLEAN!$B63 -> 64 | D63: 60 ans et + | E63: BAC+3 | F63: Conjoint | G63: 88347 | H63: 0 | I63: 0 | J63: =CLEAN!$H63+CLEAN!$I63 -> 0 | K63: 41458 | L63: =YEAR(TODAY())-YEAR(CLEAN!$K63) -> 12 | M63: 32 | N63: =SUM(CLEAN!$AB63:$AE63) -> 21 | O63: =CLEAN!$U63+CLEAN!$V63+CLEAN!$W63+CLEAN!$X63+CLEAN!$Y63+CLEAN!$Z63 -> 2116 | P63: =IF(CLEAN!$M63<=32,3,IF(CLEAN!$M63<=65,2,1)) -> 3 | Q63: =IF(Table_Market[[#This Row],[F_TOTAL_achat]]<=14,1,IF(Table_Market[[#This Row],[F_TOTAL_achat]]<=21,2,3)) -> 2 | R63: =IF(Table_Market[[#This Row],[M_TOTAL_dépensé]]<=115,1,IF(Table_Market[[#This Row],[M_TOTAL_dépensé]]<=833,2,3)) -> 3 | S63: =Table_Market[[#This Row],[R_SCORE]]&Table_Market[[#This Row],[F_SCORE]]&Table_Market[[#This Row],[M_SCORE]] -> 323 | T63: =IF(Table_Market[[#This Row],[RFM_SCORE]]="333","Clients élites",IF(LEFT(Table_Market[[#This Row],[RFM_SCORE]],1)="3","Récents prometteurs",IF(LEFT(Table_Market[[#This Row],[RFM_SCORE]],1)="1","Inactifs",IF(AND(LEFT(Table_Market[[#This Row],[RFM_SCORE]],1)>="2",MID(Table_Market[[#This Row],[RFM_SCORE]],2,1)>="2",RIGHT(Table_Market[[#This Row],[RFM_SCORE]],1)>="2"),"Fidèles rentables","Occasionnels")))) -> Récents prometteurs | U63: 1050 | V63: 178 | W63: 555 | X63: 77 | Y63: 138 | Z63: 118 | AA63: 1 | AB63: 4 | AC63: 7 | AD63: 9 | AE63: 1 | AF63: 0 | AG63: 0 | AH63: 0 | AI63: 1 | AJ63: 0 | AK63: 0 | AL63: 3 | AM63: 11 | AN63: 0
A64: 10469 | B64: 1981 | C64: =YEAR(TODAY())-CLEAN!$B64 -> 44 | D64: 30-44 ans | E64: BAC+3 | F64: Conjoint | G64: 88325 | H64: 0 | I64: 0 | J64: =CLEAN!$H64+CLEAN!$I64 -> 0 | K64: 41675 | M64: 42 | N64: =SUM(CLEAN!$AB64:$AE64) -> 19 | O64: =CLEAN!$U64+CLEAN!$V64+CLEAN!$W64+CLEAN!$X64+CLEAN!$Y64+CLEAN!$Z64 -> 1623 | P64: =IF(CLEAN!$M64<=32,3,IF(CLEAN!$M64<=65,2,1)) -> 2 | Q64: =IF(Table_Market[[#This Row],[F_TOTAL_achat]]<=14,1,IF(Table_Market[[#This Row],[F_TOTAL_achat]]<=21,2,3)) -> 2 | R64: =IF(Table_Market[[#This Row],[M_TOTAL_dépensé]]<=115,1,IF(Table_Market[[#This Row],[M_TOTAL_dépensé]]<=833,2,3)) -> 3 | S64: =Table_Market[[#This Row],[R_SCORE]]&Table_Market[[#This Row],[F_SCORE]]&Table_Market[[#This Row],[M_SCORE]] -> 223 | T64: =IF(Table_Market[[#This Row],[RFM_SCORE]]="333","Clients élites",IF(LEFT(Table_Market[[#This Row],[RFM_SCORE]],1)="3","Récents prometteurs",IF(LEFT(Table_Market[[#This Row],[RFM_SCORE]],1)="1","Inactifs",IF(AND(LEFT(Table_Market[[#This Row],[RFM_SCORE]],1)>="2",MID(Table_Market[[#This Row],[RFM_SCORE]],2,1)>="2",RIGHT(Table_Market[[#This Row],[RFM_SCORE]],1)>="2"),"Fidèles rentables","Occasionnels")))) -> Fidèles rentables | U64: 519 | V64: 71 | W64: 860 | X64: 93 | Y64: 27 | Z64: 53 | AA64: 1 | AB64: 6 | AC64: 2 | AD64: 9 | AE64: 2 | AF64: 0 | AG64: 0 | AH64: 0 | AI64: 0 | AJ64: 0 | AK64: 0 | AL64: 3 | AM64: 11 | AN64: 0
A65: 9369 | B65: 1979 | C65: =YEAR(TODAY())-CLEAN!$B65 -> 46 | D65: 45-59 ans | E65: BAC+5 | F65: Célibataire | G65: 88194 | H65: 0 | I65: 1 | J65: =CLEAN!$H65+CLEAN!$I65 -> 1 | K65: 41717 | L65: =YEAR(TODAY())-YEAR(CLEAN!$K65) -> 11 | M65: 19 | N65: =SUM(CLEAN!$AB65:$AE65) -> 36 | O65: =CLEAN!$U65+CLEAN!$V65+CLEAN!$W65+CLEAN!$X65+CLEAN!$Y65+CLEAN!$Z65 -> 1274 | P65: =IF(CLEAN!$M65<=32,3,IF(CLEAN!$M65<=65,2,1)) -> 3 | Q65: =IF(Table_Market[[#This Row],[F_TOTAL_achat]]<=14,1,IF(Table_Market[[#This Row],[F_TOTAL_achat]]<=21,2,3)) -> 3 | R65: =IF(Table_Market[[#This Row],[M_TOTAL_dépensé]]<=115,1,IF(Table_Market[[#This Row],[M_TOTAL_dépensé]]<=833,2,3)) -> 3 | S65: =Table_Market[[#This Row],[R_SCORE]]&Table_Market[[#This Row],[F_SCORE]]&Table_Market[[#This Row],[M_SCORE]] -> 333 | T65: =IF(Table_Market[[#This Row],[RFM_SCORE]]="333","Clients élites",IF(LEFT(Table_Market[[#This Row],[RFM_SCORE]],1)="3","Récents prometteurs",IF(LEFT(Table_Market[[#This Row],[RFM_SCORE]],1)="1","Inactifs",IF(AND(LEFT(Table_Market[[#This Row],[RFM_SCORE]],1)>="2",MID(Table_Market[[#This Row],[RFM_SCORE]],2,1)>="2",RIGHT(Table_Market[[#This Row],[RFM_SCORE]],1)>="2"),"Fidèles rentables","Occasionnels")))) -> Clients élites | U65: 688 | V65: 14 | W65: 309 | X65: 201 | Y65: 24 | Z65: 38 | AA65: 1 | AB65: 11 | AC65: 10 | AD65: 10 | AE65: 5 | AF65: 1 | AG65: 0 | AH65: 0 | AI65: 1 | AJ65: 0 | AK65: 0 | AL65: 3 | AM65: 11 | AN65: 1
A66: 2535 | B66: 1978 | C66: =YEAR(TODAY())-CLEAN!$B66 -> 47 | D66: 45-59 ans | E66: BAC+5 | F66: Marié | G66: 88097 | H66: 1 | I66: 0 | J66: =CLEAN!$H66+CLEAN!$I66 -> 1 | K66: 41139 | L66: =YEAR(TODAY())-YEAR(CLEAN!$K66) -> 13 | M66: 24 | N66: =SUM(CLEAN!$AB66:$AE66) -> 28 | O66: =CLEAN!$U66+CLEAN!$V66+CLEAN!$W66+CLEAN!$X66+CLEAN!$Y66+CLEAN!$Z66 -> 844 | P66: =IF(CLEAN!$M66<=32,3,IF(CLEAN!$M66<=65,2,1)) -> 3 | Q66: =IF(Table_Market[[#This Row],[F_TOTAL_achat]]<=14,1,IF(Table_Market[[#This Row],[F_TOTAL_achat]]<=21,2,3)) -> 3 | R66: =IF(Table_Market[[#This Row],[M_TOTAL_dépensé]]<=115,1,IF(Table_Market[[#This Row],[M_TOTAL_dépensé]]<=833,2,3)) -> 3 | S66: =Table_Market[[#This Row],[R_SCORE]]&Table_Market[[#This Row],[F_SCORE]]&Table_Market[[#This Row],[M_SCORE]] -> 333 | T66: =IF(Table_Market[[#This Row],[RFM_SCORE]]="333","Clients élites",IF(LEFT(Table_Market[[#This Row],[RFM_SCORE]],1)="3","Récents prometteurs",IF(LEFT(Table_Market[[#This Row],[RFM_SCORE]],1)="1","Inactifs",IF(AND(LEFT(Table_Market[[#This Row],[RFM_SCORE]],1)>="2",MID(Table_Market[[#This Row],[RFM_SCORE]],2,1)>="2",RIGHT(Table_Market[[#This Row],[RFM_SCORE]],1)>="2"),"Fidèles rentables","Occasionnels")))) -> Clients élites | U66: 163 | V66: 0 | W66: 480 | X66: 0 | Y66: 126 | Z66: 75 | AA66: 1 | AB66: 6 | AC66: 5 | AD66: 8 | AE66: 9 | AF66: 0 | AG66: 1 | AH66: 1 | AI66: 1 | AJ66: 0 | AK66: 0 | AL66: 3 | AM66: 11 | AN66: 1
A67: 3174 | B67: 1959 | C67: =YEAR(TODAY())-CLEAN!$B67 -> 66 | D67: 60 ans et + | E67: BAC+3 | F67: Conjoint | G67: 87771 | H67: 0 | I67: 1 | J67: =CLEAN!$H67+CLEAN!$I67 -> 1 | K67: 41416 | L67: =YEAR(TODAY())-YEAR(CLEAN!$K67) -> 12 | M67: 61 | N67: =SUM(CLEAN!$AB67:$AE67) -> 25 | O67: =CLEAN!$U67+CLEAN!$V67+CLEAN!$W67+CLEAN!$X67+CLEAN!$Y67+CLEAN!$Z67 -> 1957 | P67: =IF(CLEAN!$M67<=32,3,IF(CLEAN!$M67<=65,2,1)) -> 2 | Q67: =IF(Table_Market[[#This Row],[F_TOTAL_achat]]<=14,1,IF(Table_Market[[#This Row],[F_TOTAL_achat]]<=21,2,3)) -> 3 | R67: =IF(Table_Market[[#This Row],[M_TOTAL_dépensé]]<=115,1,IF(Table_Market[[#This Row],[M_TOTAL_dépensé]]<=833,2,3)) -> 3 | S67: =Table_Market[[#This Row],[R_SCORE]]&Table_Market[[#This Row],[F_SCORE]]&Table_Market[[#This Row],[M_SCORE]] -> 233 | T67: =IF(Table_Market[[#This Row],[RFM_SCORE]]="333","Clients élites",IF(LEFT(Table_Market[[#This Row],[RFM_SCORE]],1)="3","Récents prometteurs",IF(LEFT(Table_Market[[#This Row],[RFM_SCORE]],1)="1","Inactifs",IF(AND(LEFT(Table_Market[[#This Row],[RFM_SCORE]],1)>="2",MID(Table_Market[[#This Row],[RFM_SCORE]],2,1)>="2",RIGHT(Table_Market[[#This Row],[RFM_SCORE]],1)>="2"),"Fidèles rentables","Occasionnels")))) -> Fidèles rentables | U67: 1492 | V67: 38 | W67: 287 | X67: 50 | Y67: 57 | Z67: 33 | AA67: 1 | AB67: 5 | AC67: 10 | AD67: 4 | AE67: 6 | AF67: 0 | AG67: 1 | AH67: 1 | AI67: 1 | AJ67: 1 | AK67: 0 | AL67: 3 | AM67: 11 | AN67: 1
A68: 5536 | B68: 1959 | C68: =YEAR(TODAY())-CLEAN!$B68 -> 66 | D68: 60 ans et + | E68: BAC+3 | F68: Conjoint | G68: 87771 | H68: 0 | I68: 1 | J68: =CLEAN!$H68+CLEAN!$I68 -> 1 | K68: 41416 | L68: =YEAR(TODAY())-YEAR(CLEAN!$K68) -> 12 | M68: 61 | N68: =SUM(CLEAN!$AB68:$AE68) -> 25 | O68: =CLEAN!$U68+CLEAN!$V68+CLEAN!$W68+CLEAN!$X68+CLEAN!$Y68+CLEAN!$Z68 -> 1957 | P68: =IF(CLEAN!$M68<=32,3,IF(CLEAN!$M68<=65,2,1)) -> 2 | Q68: =IF(Table_Market[[#This Row],[F_TOTAL_achat]]<=14,1,IF(Table_Market[[#This Row],[F_TOTAL_achat]]<=21,2,3)) -> 3 | R68: =IF(Table_Market[[#This Row],[M_TOTAL_dépensé]]<=115,1,IF(Table_Market[[#This Row],[M_TOTAL_dépensé]]<=833,2,3)) -> 3 | S68: =Table_Market[[#This Row],[R_SCORE]]&Table_Market[[#This Row],[F_SCORE]]&Table_Market[[#This Row],[M_SCORE]] -> 233 | T68: =IF(Table_Market[[#This Row],[RFM_SCORE]]="333","Clients élites",IF(LEFT(Table_Market[[#This Row],[RFM_SCORE]],1)="3","Récents prometteurs",IF(LEFT(Table_Market[[#This Row],[RFM_SCORE]],1)="1","Inactifs",IF(AND(LEFT(Table_Market[[#This Row],[RFM_SCORE]],1)>="2",MID(Table_Market[[#This Row],[RFM_SCORE]],2,1)>="2",RIGHT(Table_Market[[#This Row],[RFM_SCORE]],1)>="2"),"Fidèles rentables","Occasionnels")))) -> Fidèles rentables | U68: 1492 | V68: 38 | W68: 287 | X68: 50 | Y68: 57 | Z68: 33 | AA68: 1 | AB68: 5 | AC68: 10 | AD68: 4 | AE68: 6 | AF68: 0 | AG68: 1 | AH68: 1 | AI68: 1 | AJ68: 1 | AK68: 0 | AL68: 3 | AM68: 11 | AN68: 1
A69: 1763 | B69: 1988 | C69: =YEAR(TODAY())-CLEAN!$B69 -> 37 | D69: 30-44 ans | E69: BAC+3 | F69: Conjoint | G69: 87679 | H69: 0 | I69: 0 | J69: =CLEAN!$H69+CLEAN!$I69 -> 0 | K69: 41482 | L69: =YEAR(TODAY())-YEAR(CLEAN!$K69) -> 12 | M69: 62 | N69: =SUM(CLEAN!$AB69:$AE69) -> 32 | O69: =CLEAN!$U69+CLEAN!$V69+CLEAN!$W69+CLEAN!$X69+CLEAN!$Y69+CLEAN!$Z69 -> 2524 | P69: =IF(CLEAN!$M69<=32,3,IF(CLEAN!$M69<=65,2,1)) -> 2 | Q69: =IF(Table_Market[[#This Row],[F_TOTAL_achat]]<=14,1,IF(Table_Market[[#This Row],[F_TOTAL_achat]]<=21,2,3)) -> 3 | R69: =IF(Table_Market[[#This Row],[M_TOTAL_dépensé]]<=115,1,IF(Table_Market[[#This Row],[M_TOTAL_dépensé]]<=833,2,3)) -> 3 | S69: =Table_Market[[#This Row],[R_SCORE]]&Table_Market[[#This Row],[F_SCORE]]&Table_Market[[#This Row],[M_SCORE]] -> 233 | T69: =IF(Table_Market[[#This Row],[RFM_SCORE]]="333","Clients élites",IF(LEFT(Table_Market[[#This Row],[RFM_SCORE]],1)="3","Récents prometteurs",IF(LEFT(Table_Market[[#This Row],[RFM_SCORE]],1)="1","Inactifs",IF(AND(LEFT(Table_Market[[#This Row],[RFM_SCORE]],1)>="2",MID(Table_Market[[#This Row],[RFM_SCORE]],2,1)>="2",RIGHT(Table_Market[[#This Row],[RFM_SCORE]],1)>="2"),"Fidèles rentables","Occasionnels")))) -> Fidèles rentables | U69: 1259 | V69: 172 | W69: 815 | X69: 97 | Y69: 148 | Z69: 33 | AA69: 1 | AB69: 7 | AC69: 11 | AD69: 10 | AE69: 4 | AF69: 1 | AG69: 0 | AH69: 1 | AI69: 1 | AJ69: 0 | AK69: 0 | AL69: 3 | AM69: 11 | AN69: 1
A70: 3619 | B70: 1960 | C70: =YEAR(TODAY())-CLEAN!$B70 -> 65 | D70: 60 ans et + | E70: BAC+5 | F70: Divorcé | G70: 87305 | H70: 0 | I70: 0 | J70: =CLEAN!$H70+CLEAN!$I70 -> 0 | K70: 41175 | L70: =YEAR(TODAY())-YEAR(CLEAN!$K70) -> 13 | M70: 19 | N70: =SUM(CLEAN!$AB70:$AE70) -> 18 | O70: =CLEAN!$U70+CLEAN!$V70+CLEAN!$W70+CLEAN!$X70+CLEAN!$Y70+CLEAN!$Z70 -> 1152 | P70: =IF(CLEAN!$M70<=32,3,IF(CLEAN!$M70<=65,2,1)) -> 3 | Q70: =IF(Table_Market[[#This Row],[F_TOTAL_achat]]<=14,1,IF(Table_Market[[#This Row],[F_TOTAL_achat]]<=21,2,3)) -> 2 | R70: =IF(Table_Market[[#This Row],[M_TOTAL_dépensé]]<=115,1,IF(Table_Market[[#This Row],[M_TOTAL_dépensé]]<=833,2,3)) -> 3 | S70: =Table_Market[[#This Row],[R_SCORE]]&Table_Market[[#This Row],[F_SCORE]]&Table_Market[[#This Row],[M_SCORE]] -> 323 | T70: =IF(Table_Market[[#This Row],[RFM_SCORE]]="333","Clients élites",IF(LEFT(Table_Market[[#This Row],[RFM_SCORE]],1)="3","Récents prometteurs",IF(LEFT(Table_Market[[#This Row],[RFM_SCORE]],1)="1","Inactifs",IF(AND(LEFT(Table_Market[[#This Row],[RFM_SCORE]],1)>="2",MID(Table_Market[[#This Row],[RFM_SCORE]],2,1)>="2",RIGHT(Table_Market[[#This Row],[RFM_SCORE]],1)>="2"),"Fidèles rentables","Occasionnels")))) -> Récents prometteurs | U70: 345 | V70: 25 | W70: 501 | X70: 63 | Y70: 138 | Z70: 80 | AA70: 1 | AB70: 5 | AC70: 3 | AD70: 8 | AE70: 2 | AF70: 0 | AG70: 0 | AH70: 1 | AI70: 0 | AJ70: 0 | AK70: 0 | AL70: 3 | AM70: 11 | AN70: 1
A71: 8908 | B71: 1959 | C71: =YEAR(TODAY())-CLEAN!$B71 -> 66 | D71: 60 ans et + | E71: BAC+3 | F71: Marié | G71: 87195 | H71: 0 | I71: 0 | J71: =CLEAN!$H71+CLEAN!$I71 -> 0 | K71: 41767 | L71: =YEAR(TODAY())-YEAR(CLEAN!$K71) -> 11 | M71: 35 | N71: =SUM(CLEAN!$AB71:$AE71) -> 20 | O71: =CLEAN!$U71+CLEAN!$V71+CLEAN!$W71+CLEAN!$X71+CLEAN!$Y71+CLEAN!$Z71 -> 1097 | P71: =IF(CLEAN!$M71<=32,3,IF(CLEAN!$M71<=65,2,1)) -> 2 | Q71: =IF(Table_Market[[#This Row],[F_TOTAL_achat]]<=14,1,IF(Table_Market[[#This Row],[F_TOTAL_achat]]<=21,2,3)) -> 2 | R71: =IF(Table_Market[[#This Row],[M_TOTAL_dépensé]]<=115,1,IF(Table_Market[[#This Row],[M_TOTAL_dépensé]]<=833,2,3)) -> 3 | S71: =Table_Market[[#This Row],[R_SCORE]]&Table_Market[[#This Row],[F_SCORE]]&Table_Market[[#This Row],[M_SCORE]] -> 223 | T71: =IF(Table_Market[[#This Row],[RFM_SCORE]]="333","Clients élites",IF(LEFT(Table_Market[[#This Row],[RFM_SCORE]],1)="3","Récents prometteurs",IF(LEFT(Table_Market[[#This Row],[RFM_SCORE]],1)="1","Inactifs",IF(AND(LEFT(Table_Market[[#This Row],[RFM_SCORE]],1)>="2",MID(Table_Market[[#This Row],[RFM_SCORE]],2,1)>="2",RIGHT(Table_Market[[#This Row],[RFM_SCORE]],1)>="2"),"Fidèles rentables","Occasionnels")))) -> Fidèles rentables | U71: 217 | V71: 76 | W71: 690 | X71: 50 | Y71: 26 | Z71: 38 | AA71: 1 | AB71: 3 | AC71: 11 | AD71: 5 | AE71: 1 | AF71: 0 | AG71: 0 | AH71: 0 | AI71: 0 | AJ71: 0 | AK71: 0 | AL71: 3 | AM71: 11 | AN71: 1
A72: 4278 | B72: 1983 | C72: =YEAR(TODAY())-CLEAN!$B72 -> 42 | D72: 30-44 ans | E72: Doctorat | F72: Célibataire | G72: 87188 | H72: 0 | I72: 0 | J72: =CLEAN!$H72+CLEAN!$I72 -> 0 | K72: 41428 | L72: =YEAR(TODAY())-YEAR(CLEAN!$K72) -> 12 | M72: 73 | N72: =SUM(CLEAN!$AB72:$AE72) -> 21 | O72: =CLEAN!$U72+CLEAN!$V72+CLEAN!$W72+CLEAN!$X72+CLEAN!$Y72+CLEAN!$Z72 -> 1923 | P72: =IF(CLEAN!$M72<=32,3,IF(CLEAN!$M72<=65,2,1)) -> 1 | Q72: =IF(Table_Market[[#This Row],[F_TOTAL_achat]]<=14,1,IF(Table_Market[[#This Row],[F_TOTAL_achat]]<=21,2,3)) -> 2 | R72: =IF(Table_Market[[#This Row],[M_TOTAL_dépensé]]<=115,1,IF(Table_Market[[#This Row],[M_TOTAL_dépensé]]<=833,2,3)) -> 3 | S72: =Table_Market[[#This Row],[R_SCORE]]&Table_Market[[#This Row],[F_SCORE]]&Table_Market[[#This Row],[M_SCORE]] -> 123 | T72: =IF(Table_Market[[#This Row],[RFM_SCORE]]="333","Clients élites",IF(LEFT(Table_Market[[#This Row],[RFM_SCORE]],1)="3","Récents prometteurs",IF(LEFT(Table_Market[[#This Row],[RFM_SCORE]],1)="1","Inactifs",IF(AND(LEFT(Table_Market[[#This Row],[RFM_SCORE]],1)>="2",MID(Table_Market[[#This Row],[RFM_SCORE]],2,1)>="2",RIGHT(Table_Market[[#This Row],[RFM_SCORE]],1)>="2"),"Fidèles rentables","Occasionnels")))) -> Inactifs | U72: 910 | V72: 111 | W72: 724 | X72: 49 | Y72: 74 | Z72: 55 | AA72: 1 | AB72: 10 | AC72: 2 | AD72: 6 | AE72: 3 | AF72: 0 | AG72: 0 | AH72: 0 | AI72: 0 | AJ72: 0 | AK72: 0 | AL72: 3 | AM72: 11 | AN72: 1
A73: 4207 | B73: 1981 | C73: =YEAR(TODAY())-CLEAN!$B73 -> 44 | D73: 30-44 ans | E73: Doctorat | F73: Marié | G73: 87171 | H73: 0 | I73: 0 | J73: =CLEAN!$H73+CLEAN!$I73 -> 0 | K73: 41395 | L73: =YEAR(TODAY())-YEAR(CLEAN!$K73) -> 12 | M73: 27 | N73: =SUM(CLEAN!$AB73:$AE73) -> 26 | O73: =CLEAN!$U73+CLEAN!$V73+CLEAN!$W73+CLEAN!$X73+CLEAN!$Y73+CLEAN!$Z73 -> 1298 | P73: =IF(CLEAN!$M73<=32,3,IF(CLEAN!$M73<=65,2,1)) -> 3 | Q73: =IF(Table_Market[[#This Row],[F_TOTAL_achat]]<=14,1,IF(Table_Market[[#This Row],[F_TOTAL_achat]]<=21,2,3)) -> 3 | R73: =IF(Table_Market[[#This Row],[M_TOTAL_dépensé]]<=115,1,IF(Table_Market[[#This Row],[M_TOTAL_dépensé]]<=833,2,3)) -> 3 | S73: =Table_Market[[#This Row],[R_SCORE]]&Table_Market[[#This Row],[F_SCORE]]&Table_Market[[#This Row],[M_SCORE]] -> 333 | T73: =IF(Table_Market[[#This Row],[RFM_SCORE]]="333","Clients élites",IF(LEFT(Table_Market[[#This Row],[RFM_SCORE]],1)="3","Récents prometteurs",IF(LEFT(Table_Market[[#This Row],[RFM_SCORE]],1)="1","Inactifs",IF(AND(LEFT(Table_Market[[#This Row],[RFM_SCORE]],1)>="2",MID(Table_Market[[#This Row],[RFM_SCORE]],2,1)>="2",RIGHT(Table_Market[[#This Row],[RFM_SCORE]],1)>="2"),"Fidèles rentables","Occasionnels")))) -> Clients élites | U73: 1001 | V73: 44 | W73: 107 | X73: 58 | Y73: 44 | Z73: 44 | AA73: 1 | AB73: 6 | AC73: 7 | AD73: 11 | AE73: 2 | AF73: 1 | AG73: 0 | AH73: 1 | AI73: 0 | AJ73: 0 | AK73: 0 | AL73: 3 | AM73: 11 | AN73: 0
A74: 2802 | B74: 1992 | C74: =YEAR(TODAY())-CLEAN!$B74 -> 33 | D74: 30-44 ans | E74: BAC+5 | F74: Marié | G74: 87000 | H74: 0 | I74: 0 | J74: =CLEAN!$H74+CLEAN!$I74 -> 0 | K74: 41258 | L74: =YEAR(TODAY())-YEAR(CLEAN!$K74) -> 13 | M74: 61 | N74: =SUM(CLEAN!$AB74:$AE74) -> 19 | O74: =CLEAN!$U74+CLEAN!$V74+CLEAN!$W74+CLEAN!$X74+CLEAN!$Y74+CLEAN!$Z74 -> 961 | P74: =IF(CLEAN!$M74<=32,3,IF(CLEAN!$M74<=65,2,1)) -> 2 | Q74: =IF(Table_Market[[#This Row],[F_TOTAL_achat]]<=14,1,IF(Table_Market[[#This Row],[F_TOTAL_achat]]<=21,2,3)) -> 2 | R74: =IF(Table_Market[[#This Row],[M_TOTAL_dépensé]]<=115,1,IF(Table_Market[[#This Row],[M_TOTAL_dépensé]]<=833,2,3)) -> 3 | S74: =Table_Market[[#This Row],[R_SCORE]]&Table_Market[[#This Row],[F_SCORE]]&Table_Market[[#This Row],[M_SCORE]] -> 223 | T74: =IF(Table_Market[[#This Row],[RFM_SCORE]]="333","Clients élites",IF(LEFT(Table_Market[[#This Row],[RFM_SCORE]],1)="3","Récents prometteurs",IF(LEFT(Table_Market[[#This Row],[RFM_SCORE]],1)="1","Inactifs",IF(AND(LEFT(Table_Market[[#This Row],[RFM_SCORE]],1)>="2",MID(Table_Market[[#This Row],[RFM_SCORE]],2,1)>="2",RIGHT(Table_Market[[#This Row],[RFM_SCORE]],1)>="2"),"Fidèles rentables","Occasionnels")))) -> Fidèles rentables | U74: 196 | V74: 25 | W74: 607 | X74: 67 | Y74: 17 | Z74: 49 | AA74: 1 | AB74: 4 | AC74: 6 | AD74: 7 | AE74: 2 | AF74: 0 | AG74: 0 | AH74: 0 | AI74: 0 | AJ74: 0 | AK74: 0 | AL74: 3 | AM74: 11 | AN74: 0
A75: 5113 | B75: 1971 | C75: =YEAR(TODAY())-CLEAN!$B75 -> 54 | D75: 45-59 ans | E75: Doctorat | F75: Divorcé | G75: 86979 | H75: 0 | I75: 0 | J75: =CLEAN!$H75+CLEAN!$I75 -> 0 | K75: 41585 | L75: =YEAR(TODAY())-YEAR(CLEAN!$K75) -> 12 | M75: 67 | N75: =SUM(CLEAN!$AB75:$AE75) -> 17 | O75: =CLEAN!$U75+CLEAN!$V75+CLEAN!$W75+CLEAN!$X75+CLEAN!$Y75+CLEAN!$Z75 -> 1702 | P75: =IF(CLEAN!$M75<=32,3,IF(CLEAN!$M75<=65,2,1)) -> 1 | Q75: =IF(Table_Market[[#This Row],[F_TOTAL_achat]]<=14,1,IF(Table_Market[[#This Row],[F_TOTAL_achat]]<=21,2,3)) -> 2 | R75: =IF(Table_Market[[#This Row],[M_TOTAL_dépensé]]<=115,1,IF(Table_Market[[#This Row],[M_TOTAL_dépensé]]<=833,2,3)) -> 3 | S75: =Table_Market[[#This Row],[R_SCORE]]&Table_Market[[#This Row],[F_SCORE]]&Table_Market[[#This Row],[M_SCORE]] -> 123 | T75: =IF(Table_Market[[#This Row],[RFM_SCORE]]="333","Clients élites",IF(LEFT(Table_Market[[#This Row],[RFM_SCORE]],1)="3","Récents prometteurs",IF(LEFT(Table_Market[[#This Row],[RFM_SCORE]],1)="1","Inactifs",IF(AND(LEFT(Table_Market[[#This Row],[RFM_SCORE]],1)>="2",MID(Table_Market[[#This Row],[RFM_SCORE]],2,1)>="2",RIGHT(Table_Market[[#This Row],[RFM_SCORE]],1)>="2"),"Fidèles rentables","Occasionnels")))) -> Inactifs | U75: 584 | V75: 100 | W75: 835 | X75: 65 | Y75: 83 | Z75: 35 | AA75: 1 | AB75: 5 | AC75: 5 | AD75: 5 | AE75: 2 | AF75: 1 | AG75: 0 | AH75: 0 | AI75: 0 | AJ75: 0 | AK75: 0 | AL75: 3 | AM75: 11 | AN75: 1
A76: 9826 | B76: 1972 | C76: =YEAR(TODAY())-CLEAN!$B76 -> 53 | D76: 45-59 ans | E76: Doctorat | F76: Célibataire | G76: 86857 | H76: 0 | I76: 0 | J76: =CLEAN!$H76+CLEAN!$I76 -> 0 | K76: 41164 | L76: =YEAR(TODAY())-YEAR(CLEAN!$K76) -> 13 | M76: 96 | N76: =SUM(CLEAN!$AB76:$AE76) -> 23 | O76: =CLEAN!$U76+CLEAN!$V76+CLEAN!$W76+CLEAN!$X76+CLEAN!$Y76+CLEAN!$Z76 -> 2114 | P76: =IF(CLEAN!$M76<=32,3,IF(CLEAN!$M76<=65,2,1)) -> 1 | Q76: =IF(Table_Market[[#This Row],[F_TOTAL_achat]]<=14,1,IF(Table_Market[[#This Row],[F_TOTAL_achat]]<=21,2,3)) -> 3 | R76: =IF(Table_Market[[#This Row],[M_TOTAL_dépensé]]<=115,1,IF(Table_Market[[#This Row],[M_TOTAL_dépensé]]<=833,2,3)) -> 3 | S76: =Table_Market[[#This Row],[R_SCORE]]&Table_Market[[#This Row],[F_SCORE]]&Table_Market[[#This Row],[M_SCORE]] -> 133 | T76: =IF(Table_Market[[#This Row],[RFM_SCORE]]="333","Clients élites",IF(LEFT(Table_Market[[#This Row],[RFM_SCORE]],1)="3","Récents prometteurs",IF(LEFT(Table_Market[[#This Row],[RFM_SCORE]],1)="1","Inactifs",IF(AND(LEFT(Table_Market[[#This Row],[RFM_SCORE]],1)>="2",MID(Table_Market[[#This Row],[RFM_SCORE]],2,1)>="2",RIGHT(Table_Market[[#This Row],[RFM_SCORE]],1)>="2"),"Fidèles rentables","Occasionnels")))) -> Inactifs | U76: 899 | V76: 102 | W76: 838 | X76: 133 | Y76: 102 | Z76: 40 | AA76: 1 | AB76: 5 | AC76: 6 | AD76: 10 | AE76: 2 | AF76: 0 | AG76: 0 | AH76: 0 | AI76: 0 | AJ76: 0 | AK76: 0 | AL76: 3 | AM76: 11 | AN76: 1
... A160: 9589 | B160: 1948 | C160: =YEAR(TODAY())-CLEAN!$B160 -> 77 | D160: 60 ans et + | E160: Doctorat | F160: Veuf | G160: 82032 | H160: 0 | I160: 0 | J160: =CLEAN!$H160+CLEAN!$I160 -> 0 | K160: 41734 | L160: =YEAR(TODAY())-YEAR(CLEAN!$K160) -> 11 | M160: 54 | N160: =SUM(CLEAN!$AB160:$AE160) -> 18 | O160: =CLEAN!$U160+CLEAN!$V160+CLEAN!$W160+CLEAN!$X160+CLEAN!$Y160+CLEAN!$Z160 -> 1234 | P160: =IF(CLEAN!$M160<=32,3,IF(CLEAN!$M160<=65,2,1)) -> 2 | Q160: =IF(Table_Market[[#This Row],[F_TOTAL_achat]]<=14,1,IF(Table_Market[[#This Row],[F_TOTAL_achat]]<=21,2,3)) -> 2 | R160: =IF(Table_Market[[#This Row],[M_TOTAL_dépensé]]<=115,1,IF(Table_Market[[#This Row],[M_TOTAL_dépensé]]<=833,2,3)) -> 3 | S160: =Table_Market[[#This Row],[R_SCORE]]&Table_Market[[#This Row],[F_SCORE]]&Table_Market[[#This Row],[M_SCORE]] -> 223 | T160: =IF(Table_Market[[#This Row],[RFM_SCORE]]="333","Clients élites",IF(LEFT(Table_Market[[#This Row],[RFM_SCORE]],1)="3","Récents prometteurs",IF(LEFT(Table_Market[[#This Row],[RFM_SCORE]],1)="1","Inactifs",IF(AND(LEFT(Table_Market[[#This Row],[RFM_SCORE]],1)>="2",MID(Table_Market[[#This Row],[RFM_SCORE]],2,1)>="2",RIGHT(Table_Market[[#This Row],[RFM_SCORE]],1)>="2"),"Fidèles rentables","Occasionnels")))) -> Fidèles rentables | U160: 332 | V160: 194 | W160: 377 | X160: 149 | Y160: 125 | Z160: 57 | AA160: 0 | AB160: 4 | AC160: 6 | AD160: 7 | AE160: 1 | AF160: 0 | AG160: 0 | AH160: 0 | AI160: 0 | AJ160: 0 | AK160: 0 | AL160: 3 | AM160: 11 | AN160: 0
A161: 6810 | B161: 1983 | C161: =YEAR(TODAY())-CLEAN!$B161 -> 42 | D161: 30-44 ans | E161: BAC+3 | F161: Divorcé | G161: 82025 | H161: 0 | I161: 0 | J161: =CLEAN!$H161+CLEAN!$I161 -> 0 | K161: 41422 | M161: 76 | N161: =SUM(CLEAN!$AB161:$AE161) -> 12 | O161: =CLEAN!$U161+CLEAN!$V161+CLEAN!$W161+CLEAN!$X161+CLEAN!$Y161+CLEAN!$Z161 -> 1187 | P161: =IF(CLEAN!$M161<=32,3,IF(CLEAN!$M161<=65,2,1)) -> 1 | Q161: =IF(Table_Market[[#This Row],[F_TOTAL_achat]]<=14,1,IF(Table_Market[[#This Row],[F_TOTAL_achat]]<=21,2,3)) -> 1 | R161: =IF(Table_Market[[#This Row],[M_TOTAL_dépensé]]<=115,1,IF(Table_Market[[#This Row],[M_TOTAL_dépensé]]<=833,2,3)) -> 3 | S161: =Table_Market[[#This Row],[R_SCORE]]&Table_Market[[#This Row],[F_SCORE]]&Table_Market[[#This Row],[M_SCORE]] -> 113 | T161: =IF(Table_Market[[#This Row],[RFM_SCORE]]="333","Clients élites",IF(LEFT(Table_Market[[#This Row],[RFM_SCORE]],1)="3","Récents prometteurs",IF(LEFT(Table_Market[[#This Row],[RFM_SCORE]],1)="1","Inactifs",IF(AND(LEFT(Table_Market[[#This Row],[RFM_SCORE]],1)>="2",MID(Table_Market[[#This Row],[RFM_SCORE]],2,1)>="2",RIGHT(Table_Market[[#This Row],[RFM_SCORE]],1)>="2"),"Fidèles rentables","Occasionnels")))) -> Inactifs | U161: 267 | V161: 98 | W161: 606 | X161: 48 | Y161: 70 | Z161: 98 | AA161: 1 | AB161: 3 | AC161: 2 | AD161: 6 | AE161: 1 | AF161: 0 | AG161: 0 | AH161: 1 | AI161: 0 | AJ161: 0 | AK161: 0 | AL161: 3 | AM161: 11 | AN161: 1
A162: 10446 | B162: 1957 | C162: =YEAR(TODAY())-CLEAN!$B162 -> 68 | D162: 60 ans et + | E162: Doctorat | F162: Marié | G162: 82017 | H162: 0 | I162: 0 | J162: =CLEAN!$H162+CLEAN!$I162 -> 0 | K162: 41220 | L162: =YEAR(TODAY())-YEAR(CLEAN!$K162) -> 13 | M162: 58 | N162: =SUM(CLEAN!$AB162:$AE162) -> 18 | O162: =CLEAN!$U162+CLEAN!$V162+CLEAN!$W162+CLEAN!$X162+CLEAN!$Y162+CLEAN!$Z162 -> 729 | P162: =IF(CLEAN!$M162<=32,3,IF(CLEAN!$M162<=65,2,1)) -> 2 | Q162: =IF(Table_Market[[#This Row],[F_TOTAL_achat]]<=14,1,IF(Table_Market[[#This Row],[F_TOTAL_achat]]<=21,2,3)) -> 2 | R162: =IF(Table_Market[[#This Row],[M_TOTAL_dépensé]]<=115,1,IF(Table_Market[[#This Row],[M_TOTAL_dépensé]]<=833,2,3)) -> 2 | S162: =Table_Market[[#This Row],[R_SCORE]]&Table_Market[[#This Row],[F_SCORE]]&Table_Market[[#This Row],[M_SCORE]] -> 222 | T162: =IF(Table_Market[[#This Row],[RFM_SCORE]]="333","Clients élites",IF(LEFT(Table_Market[[#This Row],[RFM_SCORE]],1)="3","Récents prometteurs",IF(LEFT(Table_Market[[#This Row],[RFM_SCORE]],1)="1","Inactifs",IF(AND(LEFT(Table_Market[[#This Row],[RFM_SCORE]],1)>="2",MID(Table_Market[[#This Row],[RFM_SCORE]],2,1)>="2",RIGHT(Table_Market[[#This Row],[RFM_SCORE]],1)>="2"),"Fidèles rentables","Occasionnels")))) -> Fidèles rentables | U162: 184 | V162: 23 | W162: 446 | X162: 30 | Y162: 23 | Z162: 23 | AA162: 1 | AB162: 5 | AC162: 4 | AD162: 7 | AE162: 2 | AF162: 0 | AG162: 1 | AH162: 1 | AI162: 1 | AJ162: 0 | AK162: 0 | AL162: 3 | AM162: 11 | AN162: 1
A163: 8395 | B163: 1961 | C163: =YEAR(TODAY())-CLEAN!$B163 -> 64 | D163: 60 ans et + | E163: BAC+3 | F163: Célibataire | G163: 82014 | H163: 0 | I163: 0 | J163: =CLEAN!$H163+CLEAN!$I163 -> 0 | K163: 41141 | L163: =YEAR(TODAY())-YEAR(CLEAN!$K163) -> 13 | M163: 48 | N163: =SUM(CLEAN!$AB163:$AE163) -> 27 | O163: =CLEAN!$U163+CLEAN!$V163+CLEAN!$W163+CLEAN!$X163+CLEAN!$Y163+CLEAN!$Z163 -> 1511 | P163: =IF(CLEAN!$M163<=32,3,IF(CLEAN!$M163<=65,2,1)) -> 2 | Q163: =IF(Table_Market[[#This Row],[F_TOTAL_achat]]<=14,1,IF(Table_Market[[#This Row],[F_TOTAL_achat]]<=21,2,3)) -> 3 | R163: =IF(Table_Market[[#This Row],[M_TOTAL_dépensé]]<=115,1,IF(Table_Market[[#This Row],[M_TOTAL_dépensé]]<=833,2,3)) -> 3 | S163: =Table_Market[[#This Row],[R_SCORE]]&Table_Market[[#This Row],[F_SCORE]]&Table_Market[[#This Row],[M_SCORE]] -> 233 | T163: =IF(Table_Market[[#This Row],[RFM_SCORE]]="333","Clients élites",IF(LEFT(Table_Market[[#This Row],[RFM_SCORE]],1)="3","Récents prometteurs",IF(LEFT(Table_Market[[#This Row],[RFM_SCORE]],1)="1","Inactifs",IF(AND(LEFT(Table_Market[[#This Row],[RFM_SCORE]],1)>="2",MID(Table_Market[[#This Row],[RFM_SCORE]],2,1)>="2",RIGHT(Table_Market[[#This Row],[RFM_SCORE]],1)>="2"),"Fidèles rentables","Occasionnels")))) -> Fidèles rentables | U163: 980 | V163: 37 | W163: 265 | X163: 35 | Y163: 163 | Z163: 31 | AA163: 1 | AB163: 3 | AC163: 6 | AD163: 12 | AE163: 6 | AF163: 0 | AG163: 0 | AH163: 0 | AI163: 0 | AJ163: 0 | AK163: 0 | AL163: 3 | AM163: 11 | AN163: 1
A164: 5341 | B164: 1962 | C164: =YEAR(TODAY())-CLEAN!$B164 -> 63 | D164: 60 ans et + | E164: BAC+5 | F164: Divorcé | G164: 81975 | H164: 0 | I164: 1 | J164: =CLEAN!$H164+CLEAN!$I164 -> 1 | K164: 41279 | L164: =YEAR(TODAY())-YEAR(CLEAN!$K164) -> 12 | M164: 2 | N164: =SUM(CLEAN!$AB164:$AE164) -> 20 | O164: =CLEAN!$U164+CLEAN!$V164+CLEAN!$W164+CLEAN!$X164+CLEAN!$Y164+CLEAN!$Z164 -> 1588 | P164: =IF(CLEAN!$M164<=32,3,IF(CLEAN!$M164<=65,2,1)) -> 3 | Q164: =IF(Table_Market[[#This Row],[F_TOTAL_achat]]<=14,1,IF(Table_Market[[#This Row],[F_TOTAL_achat]]<=21,2,3)) -> 2 | R164: =IF(Table_Market[[#This Row],[M_TOTAL_dépensé]]<=115,1,IF(Table_Market[[#This Row],[M_TOTAL_dépensé]]<=833,2,3)) -> 3 | S164: =Table_Market[[#This Row],[R_SCORE]]&Table_Market[[#This Row],[F_SCORE]]&Table_Market[[#This Row],[M_SCORE]] -> 323 | T164: =IF(Table_Market[[#This Row],[RFM_SCORE]]="333","Clients élites",IF(LEFT(Table_Market[[#This Row],[RFM_SCORE]],1)="3","Récents prometteurs",IF(LEFT(Table_Market[[#This Row],[RFM_SCORE]],1)="1","Inactifs",IF(AND(LEFT(Table_Market[[#This Row],[RFM_SCORE]],1)>="2",MID(Table_Market[[#This Row],[RFM_SCORE]],2,1)>="2",RIGHT(Table_Market[[#This Row],[RFM_SCORE]],1)>="2"),"Fidèles rentables","Occasionnels")))) -> Récents prometteurs | U164: 983 | V164: 76 | W164: 184 | X164: 180 | Y164: 138 | Z164: 27 | AA164: 1 | AB164: 6 | AC164: 3 | AD164: 4 | AE164: 7 | AF164: 0 | AG164: 0 | AH164: 1 | AI164: 0 | AJ164: 0 | AK164: 0 | AL164: 3 | AM164: 11 | AN164: 0
A165: 1103 | B165: 1976 | C165: =YEAR(TODAY())-CLEAN!$B165 -> 49 | D165: 45-59 ans | E165: BAC+5 | F165: Marié | G165: 81929 | H165: 1 | I165: 0 | J165: =CLEAN!$H165+CLEAN!$I165 -> 1 | K165: 41181 | L165: =YEAR(TODAY())-YEAR(CLEAN!$K165) -> 13 | M165: 60 | N165: =SUM(CLEAN!$AB165:$AE165) -> 24 | O165: =CLEAN!$U165+CLEAN!$V165+CLEAN!$W165+CLEAN!$X165+CLEAN!$Y165+CLEAN!$Z165 -> 2053 | P165: =IF(CLEAN!$M165<=32,3,IF(CLEAN!$M165<=65,2,1)) -> 2 | Q165: =IF(Table_Market[[#This Row],[F_TOTAL_achat]]<=14,1,IF(Table_Market[[#This Row],[F_TOTAL_achat]]<=21,2,3)) -> 3 | R165: =IF(Table_Market[[#This Row],[M_TOTAL_dépensé]]<=115,1,IF(Table_Market[[#This Row],[M_TOTAL_dépensé]]<=833,2,3)) -> 3 | S165: =Table_Market[[#This Row],[R_SCORE]]&Table_Market[[#This Row],[F_SCORE]]&Table_Market[[#This Row],[M_SCORE]] -> 233 | T165: =IF(Table_Market[[#This Row],[RFM_SCORE]]="333","Clients élites",IF(LEFT(Table_Market[[#This Row],[RFM_SCORE]],1)="3","Récents prometteurs",IF(LEFT(Table_Market[[#This Row],[RFM_SCORE]],1)="1","Inactifs",IF(AND(LEFT(Table_Market[[#This Row],[RFM_SCORE]],1)>="2",MID(Table_Market[[#This Row],[RFM_SCORE]],2,1)>="2",RIGHT(Table_Market[[#This Row],[RFM_SCORE]],1)>="2"),"Fidèles rentables","Occasionnels")))) -> Fidèles rentables | U165: 1486 | V165: 55 | W165: 278 | X165: 49 | Y165: 0 | Z165: 185 | AA165: 2 | AB165: 4 | AC165: 4 | AD165: 10 | AE165: 6 | AF165: 1 | AG165: 0 | AH165: 1 | AI165: 0 | AJ165: 0 | AK165: 0 | AL165: 3 | AM165: 11 | AN165: 1
A166: 1650 | B166: 1960 | C166: =YEAR(TODAY())-CLEAN!$B166 -> 65 | D166: 60 ans et + | E166: BAC+5 | F166: Marié | G166: 81843 | H166: 0 | I166: 0 | J166: =CLEAN!$H166+CLEAN!$I166 -> 0 | K166: 41386 | L166: =YEAR(TODAY())-YEAR(CLEAN!$K166) -> 12 | M166: 13 | N166: =SUM(CLEAN!$AB166:$AE166) -> 29 | O166: =CLEAN!$U166+CLEAN!$V166+CLEAN!$W166+CLEAN!$X166+CLEAN!$Y166+CLEAN!$Z166 -> 1643 | P166: =IF(CLEAN!$M166<=32,3,IF(CLEAN!$M166<=65,2,1)) -> 3 | Q166: =IF(Table_Market[[#This Row],[F_TOTAL_achat]]<=14,1,IF(Table_Market[[#This Row],[F_TOTAL_achat]]<=21,2,3)) -> 3 | R166: =IF(Table_Market[[#This Row],[M_TOTAL_dépensé]]<=115,1,IF(Table_Market[[#This Row],[M_TOTAL_dépensé]]<=833,2,3)) -> 3 | S166: =Table_Market[[#This Row],[R_SCORE]]&Table_Market[[#This Row],[F_SCORE]]&Table_Market[[#This Row],[M_SCORE]] -> 333 | T166: =IF(Table_Market[[#This Row],[RFM_SCORE]]="333","Clients élites",IF(LEFT(Table_Market[[#This Row],[RFM_SCORE]],1)="3","Récents prometteurs",IF(LEFT(Table_Market[[#This Row],[RFM_SCORE]],1)="1","Inactifs",IF(AND(LEFT(Table_Market[[#This Row],[RFM_SCORE]],1)>="2",MID(Table_Market[[#This Row],[RFM_SCORE]],2,1)>="2",RIGHT(Table_Market[[#This Row],[RFM_SCORE]],1)>="2"),"Fidèles rentables","Occasionnels")))) -> Clients élites | U166: 779 | V166: 86 | W166: 537 | X166: 34 | Y166: 69 | Z166: 138 | AA166: 1 | AB166: 5 | AC166: 9 | AD166: 12 | AE166: 3 | AF166: 0 | AG166: 0 | AH166: 0 | AI166: 0 | AJ166: 0 | AK166: 0 | AL166: 3 | AM166: 11 | AN166: 0
